Lmod has detected the following error: These module(s) or extension(s) exist
but cannot be loaded as requested: "Anaconda3"
   Try: "module spider Anaconda3" to see how to load the module(s).



Lmod has detected the following error: The following module(s) are unknown:
"CUDA/12.2"

Please check the spelling or version number. Also try "module spider ..."
It is also possible your cache file is out-of-date; it may help to try:
  $ module --ignore_cache load "CUDA/12.2"

Also make sure that all modulefiles written in TCL start with the string
#%Module



/cluster/apps/eb/software/Anaconda3/2023.09-0/bin/conda: line 3: import: command not found
/cluster/apps/eb/software/Anaconda3/2023.09-0/bin/conda: line 6: syntax error near unexpected token `sys.argv'
/cluster/apps/eb/software/Anaconda3/2023.09-0/bin/conda: line 6: `if len(sys.argv) > 1 and sys.argv[1].startswith('shell.') and sys.path and sys.path[0] == '':'
Traceback (most recent call last):
  File "/cluster/home/evaajo/vi_mini_project/program.py", line 77, in <module>
    results = model.train(
              ^^^^^^^^^^^^
  File "/cluster/home/evaajo/.local/lib/python3.11/site-packages/ultralytics/engine/model.py", line 802, in train
    self.trainer.train()
  File "/cluster/home/evaajo/.local/lib/python3.11/site-packages/ultralytics/engine/trainer.py", line 207, in train
    self._do_train(world_size)
  File "/cluster/home/evaajo/.local/lib/python3.11/site-packages/ultralytics/engine/trainer.py", line 327, in _do_train
    self._setup_train(world_size)
  File "/cluster/home/evaajo/.local/lib/python3.11/site-packages/ultralytics/engine/trainer.py", line 291, in _setup_train
    self.train_loader = self.get_dataloader(self.trainset, batch_size=batch_size, rank=LOCAL_RANK, mode="train")
                        ^^^^^^^^^^^^^^^^^^^^^^^^^^^^^^^^^^^^^^^^^^^^^^^^^^^^^^^^^^^^^^^^^^^^^^^^^^^^^^^^^^^^^^^^
  File "/cluster/home/evaajo/.local/lib/python3.11/site-packages/ultralytics/models/yolo/detect/train.py", line 49, in get_dataloader
    dataset = self.build_dataset(dataset_path, mode, batch_size)
              ^^^^^^^^^^^^^^^^^^^^^^^^^^^^^^^^^^^^^^^^^^^^^^^^^^
  File "/cluster/home/evaajo/.local/lib/python3.11/site-packages/ultralytics/models/yolo/detect/train.py", line 43, in build_dataset
    return build_yolo_dataset(self.args, img_path, batch, self.data, mode=mode, rect=mode == "val", stride=gs)
           ^^^^^^^^^^^^^^^^^^^^^^^^^^^^^^^^^^^^^^^^^^^^^^^^^^^^^^^^^^^^^^^^^^^^^^^^^^^^^^^^^^^^^^^^^^^^^^^^^^^
  File "/cluster/home/evaajo/.local/lib/python3.11/site-packages/ultralytics/data/build.py", line 87, in build_yolo_dataset
    return dataset(
           ^^^^^^^^
  File "/cluster/home/evaajo/.local/lib/python3.11/site-packages/ultralytics/data/dataset.py", line 64, in __init__
    super().__init__(*args, **kwargs)
  File "/cluster/home/evaajo/.local/lib/python3.11/site-packages/ultralytics/data/base.py", line 74, in __init__
    self.labels = self.get_labels()
                  ^^^^^^^^^^^^^^^^^
  File "/cluster/home/evaajo/.local/lib/python3.11/site-packages/ultralytics/data/dataset.py", line 138, in get_labels
    cache, exists = load_dataset_cache_file(cache_path), True  # attempt to load a *.cache file
                    ^^^^^^^^^^^^^^^^^^^^^^^^^^^^^^^^^^^
  File "/cluster/home/evaajo/.local/lib/python3.11/site-packages/ultralytics/data/utils.py", line 659, in load_dataset_cache_file
    cache = np.load(str(path), allow_pickle=True).item()  # load dict
            ^^^^^^^^^^^^^^^^^^^^^^^^^^^^^^^^^^^^^
  File "/cluster/apps/eb/software/Anaconda3/2023.09-0/lib/python3.11/site-packages/numpy/lib/npyio.py", line 432, in load
    return format.read_array(fid, allow_pickle=allow_pickle,
           ^^^^^^^^^^^^^^^^^^^^^^^^^^^^^^^^^^^^^^^^^^^^^^^^^
  File "/cluster/apps/eb/software/Anaconda3/2023.09-0/lib/python3.11/site-packages/numpy/lib/format.py", line 792, in read_array
    array = pickle.load(fp, **pickle_kwargs)
            ^^^^^^^^^^^^^^^^^^^^^^^^^^^^^^^^
ModuleNotFoundError: No module named 'numpy._core'
